Workbook

Sheet 26
A1: Дата | B1: Приход | C1: Расход | D1: Комментарий | E1: =TODAY()-DATE(YEAR(TODAY()),1,1) -> 96 | F1: Дней с начала года прошло
B2: =SUM(B4:B1061) -> 6802079 | C2: =SUM(C4:C1061) -> 6183007 | E2: =B3/E1 -> 6448.6667 | F2: Средний доход за день
A3: остаток | B3: =B2-C2 -> 619072 | E3: =E2/8 -> 806.08333 | F3: =E3*160 -> 128973.33 | G3: Среднее за час\месяц
A4: 46029 | C4: 15000 | D4: Алишщер и Саид за станок
C5: 10000 | D5: егор за станок
C6: 15000 | D6: антон за станок
C7: 6000 | D7: фрезы
C8: 43920 | D8: аренда
C9: 2000 | D9: фреза
C10: 10900 | D10: электричество дек
B11: 20000 | C11: 20000 | D11: продал печку и отдал егору
C12: 1250 | D12: фреза
A13: 46041 | B13: 5000 | C13: 2000 | D13: балансировка импеллера Игорь
A14: 46048 | B14: 1149999 | C14: 115000 | D14: техновент об
C15: 4060 | D15: резец и фрезы
C16: 2500 | D16: заготовки на проходной элемент клеемазалка
C17: 7040 | D17: проходной элемент клеемазалка
C18: 3490 | D18: латунь на клеемазалку
A19: 46052 | C19: 977500 | D19: техновент об
A20: 46058 | C20: 14500 | D20: электричество янв
A21: 46064 | B21: 50000 | D21: Иван Постников за качалку.
A22: 46067 | B22: 70000 | D22: Ваган за бублик
A23: 46071 | B23: 6000 | D23: ремонт хуйни от дукато
B24: 20000 | C24: 2000 | D24: Цельсий за фланцы
A25: 46077 | C25: 15000 | D25: тумбочка
A26: 46078 | B26: 30100 | C26: 3010 | D26: Цельсий за переходные пластины
A27: 46079 | B27: 10000 | D27: шлифовка ножа
A28: 46083 | B28: 2250000 | C28: =B28*0.1 -> 225000 | D28: технеовент
B29: 40000 | C29: 4000 | D29: акон-техно корпуса 5 шт
C30: 44000 | D30: аренда
C31: 20000 | D31: электричество
C32: 1000 | D32: пруток нержи
A33: 46084 | C33: 36000 | D33: электроиспытания клеемазалки
A34: 46085 | B34: 20000 | C34: 2000 | D34: овен
A35: 46087 | C35: 3500 | D35: оправки БТ40
C36: 1300 | D36: Краеискатель
A37: 46088 | B37: 17000 | D37: Николай радиаторы
C38: 1912500 | D38: техновент об
A39: 46089 | C39: 4000 | D39: какая-то хуйня
A40: 46092 | B40: 54600 | C40: 5460 | D40: акон-техно остаточ за корпуса
...

Sheet 25
A1: Дата | B1: Приход | C1: Расход | D1: Комментарий | E1: 365 | F1: Дней с начала года прошло
B2: =SUM(B4:B1061) -> 30237702 | C2: =SUM(C4:C1061) -> 13443202 | E2: =B3/E1 -> 46012.33 | F2: Средний доход за день
A3: остаток | B3: =B2-C2 -> 16794501 | E3: =E2/8 -> 5751.5413 | F3: =E3*160 -> 920246.61 | G3: Среднее за час\месяц
A4: 45666 | C4: 11860 | D4: прутки
C5: 38200 | D5: аренда дек
C6: 24348 | D6: пневматика на пресс
A7: 45667 | B7: 6600 | C7: 396 | D7: ролик Регат Тайм
C8: 11140.85 | D8: электричество дек.
C9: 11739 | D9: чип и дип
A10: 45672 | C10: 6000 | D10: алишер за помост
C11: 6700 | D11: алюминий на помост
C12: 3500 | D12: всякое
A13: 45675 | B13: 42750 | C13: 2565 | D13: интертекстиль
A14: 45677 | C14: 43000 | D14: наладка чпу
A15: 45678 | C15: 1300 | D15: метчики
B16: 5000 | D16: ваган за маркировку
C17: 5000 | D17: валера аванс за переделку дырок на БХВ
C18: 1000 | D18: смыслов за точилку
A19: 45681 | B19: 25000 | C19: 1500 | D19: эконацпроект за проставочные кольца
C20: 23000 | D20: алёна за резку на гриндер
C21: 2122 | D21: краны на клеемазалку
C22: 935 | D22: сдэк за пневматику
C23: 1070 | D23: сверло т\с
C24: 13500 | D24: Валере за переделку дырок на БХВ
C25: 8700 | D25: ригшеля на гриндер
A26: 45684 | B26: 1054771 | C26: 63287 | D26: Цельсий для юры
B27: 1000000 | C27: 60000 | D27: ТПИ промаванс за хвосты
C28: 4660 | D28: прутки за материал на 2 вала
A29: 45685 | C29: 7500 | D29: валера переделка чайников
C30: 2000 | D30: алишер аванс
C31: 9317 | D31: аванс за метал для эдуарда и на большие железки хвостов
B32: 13000 | C32: 33000 | D32: денис резка на пресс 16мм
C33: 40000 | D33: доплата за металл
C34: 50000 | D34: алёна резка пластин на ТПИ
C35: 9800 | D35: сож
C36: 1500 | D36: хз
A37: 45692 | C37: 8050 | D37: электричество янв
C38: 32800 | D38: аренда дек
C39: 3500 | D39: ваган опоры
C40: 2500 | D40: гайки
...

Sheet 24
A1: Дата | B1: Приход | C1: Расход | D1: Комментарий | E1: 365 | F1: Дней с начала года прошло
B2: =SUM(B4:B1040) -> 15229575 | C2: =SUM(C4:C1040) -> 10403067 | E2: =B3/E1 -> 13223.31 | F2: Средний доход за день
A3: остаток | B3: =B2-C2 -> 4826508.2 | E3: =E2/8 -> 1652.9138 | F3: =E3*160 -> 264466.2 | G3: Среднее за час\месяц
A4: 45302 | B4: 4000 | D4: не помню
C5: 20000 | D5: всякой херни напокупал
C6: 17000 | D6: профилометр
C7: 4750 | D7: цанговый патрон и патрон на чпу
C8: 17000 | D8: профилометр
C9: 1750 | D9: резцы
C10: 32800 | D10: аренда
A11: 45303 | B11: 14000 | D11: Магомет ножи
A12: 45306 | B12: 4400 | C12: 264 | D12: ПК Возрождение за штифты
B13: 72400 | C13: 4344 | D13: Синглкап за корпуса шнеков и заточку ножей
B14: 50000 | C14: 3000 | D14: Интертекстиль, модели нижнего стерднего и верхнего этажа
A15: 45307 | B15: 53220 | C15: 3194 | D15: Интертекстиль, модели размотчика и промежуточного этажа и сварку основания
C16: 15000 | D16: Валере за сварку основания
A17: 45311 | B17: 6000 | D17: Олег шлифовка ножей
A18: 45313 | C18: 11238 | D18: переменка декабрь
C19: 88000 | D19: насос для клеемазалки
C20: 37680 | D20: аванс 50% за пневмомал для клеемазалки
C21: 84770 | D21: частотники для клеемазки
C22: 4450 | D22: щуп профилометра
A23: 45314 | B23: 15000 | C23: 900 | D23: Долта за шлифовку ножей
A24: 45316 | C24: 690000 | D24: лазер на клеемазку
C25: 38230 | D25: прутки материал на Долту и бинтомоты
C26: 2200 | D26: полоса в запас
A27: 45317 | B27: 43250 | C27: 2595 | D27: интертекстись бинтомот комплект гнутого железа
C28: 22000 | D28: глазков за комплект на бинтомот
B29: 10000 | C29: 600 | D29: типография за вал
C30: 10000 | D30: доставка лазера
A31: 45322 | B31: 20000 | D31: Вагиф детали для ижа
C32: 1100 | D32: прокладки на компрессор
A33: 45324 | B33: 75400 | C33: 4524 | D33: интертекстиль за детали узла размотки
B34: 5500 | C34: 330 | D34: кофепод за ремонт утюга
C35: 9963 | D35: переменка январь
A36: 45325 | C36: 30000 | D36: валере за мебель на 2 этаж
C37: 65400 | D37: Юре чпу февраль
C38: 3500 | D38: пружины на ТПИ и сверло на бинтомот
A39: 45388 | C39: 750 | D39: деловые за доставку частотников
A40: 45389 | C40: 12500 | D40: столещницы
...

Sheet 23
A1: Дата | B1: Приход | C1: Расход | D1: Комментарий | E1: 365 | F1: Дней с начала года прошло
B2: =SUM(B4:B1038) -> 13361210 | C2: =SUM(C4:C1038) -> 7687884.7 | E2: =B3/E1 -> 15543.357 | F2: Средний доход за день
A3: остаток | B3: =B2-C2 -> 5673325.3 | E3: =E2/8 -> 1942.9196 | F3: =E3*160 -> 310867.14 | G3: Среднее за час\месяц
A4: 44938 | B4: 828923 | C4: 49735 | D4: за пенорезку
C5: 5491 | D5: свет за нояб-декаб
C6: 30000 | D6: всякая хрень
C7: 14200 | D7: глазкову за резку Александра, Шайзенверка и ЭССП
B8: 5000 | D8: Вагиф за сварку коллектора и шлифовку проставок
B9: 4000 | D9: олег за завтуливание дизель-генератора
C10: 6500 | D10: прутки ру
A11: 44939 | B11: 12000 | D11: дозаторы для сахара
C12: 1800 | D12: железки с директлота
B13: 2000 | D13: заварил рампу
B14: 3000 | D14: Вагиф за сворку ушка карба
A15: 44941 | B15: 10000 | D15: от александра за шаблоны для токарного
A16: 44942 | B16: 10000 | D16: Илья макаронник за валшестерню
C17: 9500 | D17: спецовка
A18: 44944 | C18: 1000 | D18: паше за помощь
C19: 6000 | D19: направляйки с алика
B20: 12000 | C20: 720 | D20: от Славы за две резалки
A21: 44946 | C21: 7000 | D21: Глазкову за резку на тестя, шайзерверк и синглкап
A22: 44949 | C22: 10000 | D22: Александру за эрозию подшипников для ЭССП и роликов для ИЮМ климат
C23: 10000 | D23: Александру за резьбошлифовку для ЭССП
C24: 150 | D24: развёртка
C25: 1744 | D25: мелочи в ВИ
B26: 35000 | C26: 2100 | D26: Синглкап
B27: 19000 | C27: 1140 | D27: ЮИМ климат два шпонпаза в калёнке +два ролика на иговку
A28: 44950 | B28: 5100 | D28: от фёдора за покраску
C29: 2500 | D29: Валере за покраску фёдора
C30: 16000 | D30: Алёне за резку резины
A31: 44952 | C31: 580000 | D31: эрозия
C32: 13500 | D32: доставка эрозии
C33: 1500 | D33: разгрузка
A34: 270123 | C34: 1092 | D34: подши на вибросито
C35: 5000 | D35: виброопоры
C36: 810 | D36: железки с директлота
C37: 2500 | D37: железки с директлота
B38: 9400 | C38: 564 | D38: СЗС винты и муфточка
A39: 44956 | C39: 4400 | D39: круг на киплайн +латунь на толкатели синглкап +45 на вал кирьянову
B40: 10000 | D40: валшестерня на макароны
...

Sheet 22
A1: Дата | B1: Приход | C1: Расход | D1: Комментарий | E1: 365 | F1: Дней с начала года прошло
B2: =SUM(B4:B2152) -> 10224884 | C2: =SUM(C4:C2152) -> 6327440.5 | E2: =B3/E1 -> 10677.926 | F2: Средний доход за день
A3: остаток | B3: =B2-C2 -> 3897443.1 | E3: =E2/8 -> 1334.7408 | F3: =E3*160 -> 213558.53 | G3: Среднее за час\месяц
A4: 44564 | C4: 10000 | D4: Глазкову за вал
A5: 44567 | C5: 2000 | D5: Валере за покрасту подтумбочек мистер дорс
C6: 2000 | D6: всякая мелочь
B7: 6000 | D7: проточка валов
A8: 44206 | C8: 600 | D8: шлифдиски на плоскошлиф
C9: 6000 | D9: песочка ракет
C10: 2000 | D10: фрещза
A11: 44207 | B11: 20500 | D11: от Кирьянова за корпус намотчика, трубу намотчика и проточку трубы кристаллизатора
A12: 44208 | B12: 10000 | D12: от кирьянова аванс за раму
B13: 2000 | D13: шайбы регулировочные
A14: 44209 | B14: 2000 | D14: фрезеровка каикх-то карманов
B15: 20000 | D15: от Юры за аренду январь
C16: 40386 | D16: аренда янв
C17: 2460 | D17: электричество декабрь.
A18: 44575 | B18: 3000 | D18: Кирьянов проточка трубы +барабанчик для свинца
B19: 20000 | D19: Ольховский промаванс за ракеты
C20: 1600 | D20: 123 блоки
A21: 44576 | C21: 6500 | D21: Ольховский матовая палка
C22: 6000 | D22: Валере за покраску ракет
A23: 44580 | C23: 558 | D23: краска на ракеты
C24: 57 | D24: гайки
C25: 7777 | D25: клёпки на ракеты, шланг на плоскошлиф, лампы для плоскошлифа
A26: 44581 | C26: 2440 | D26: электрофигня на ракеты
C27: 700 | D27: Гохе за шлифдиски
A28: 44582 | B28: 1600 | D28: сварил кастрюлю
C29: 7500 | D29: Глазкову за резку на Кирьянова и Александра
B30: 66000 | D30: о Ольховского за ракеты
A31: 44584 | B31: 8000 | D31: от Александра за штурвальчик и два болта,
B32: 1600 | D32: сварил батут
B33: 2200 | D33: ремонт конуса Глеб
C34: 132 | D34: налог
B35: 1600 | D35: сварил коляску
A36: 44588 | C36: 3570 | D36: железо из прутков
C37: 170 | D37: свёрла
A38: 44589 | B38: 40000 | D38: Павел аванс за козырёк из 54К
A39: 44590 | B39: 25000 | D39: Кирьянов ремонт головки кристаллизатора
A40: 44591 | C40: 8500 | D40: угловая приставка
...

Sheet 21
A1: Дата | B1: Приход | C1: Расход | D1: Комментарий | E1: 365 | F1: Дней с начала года прошло
B2: =SUM(B4:B2143) -> 4818296 | C2: =SUM(C4:C2143) -> 2491250.8 | E2: =B3/E1 -> 6375.4664 | F2: Средний доход за день
A3: остаток | B3: =B2-C2 -> 2327045.2 | E3: =E2/8 -> 796.9333 | F3: =E3*160 -> 127509.33 | G3: Среднее за час\месяц
A4: 44201 | B4: 5000 | D4: рассверлил Вепрю раму
B5: 2000 | D5: работы по прикладу Вепрь
B6: 10000 | D6: от Кмузова аванс за кресла (по 3500 штука)
A7: 44202 | C7: 1640 | D7: металл на зиговку
A8: 44208 | C8: 6500 | D8: валы на зиговку
C9: 8400 | D9: частотник на зиговку
A10: 44209 | B10: 15000 | D10: от Александра за подтумбочки мр.Дорс. 7250 х 6шт = 43500
C11: 3600 | D11: Антону за овальную трубу для Кмузова
B12: 1700 | D12: сварил кусок инвколяски
A13: 44210 | C13: 13300 | D13: распил на Зиговку, пульт Орехову, проушины на сидения Кмузову, мистердорс
A14: 44211 | C14: 260 | D14: метизы на сиденья Кмузову
C15: 2600 | D15: электрошкаф на чпу
A16: 44213 | C16: 5650 | D16: блоки питания на ЧПУшку
C17: 1300 | D17: электромелочь на ЧПУшку
C18: 250 | D18: винты на кресла Кмузова
B19: 10000 | D19: от Кмузова за кресла (2500 должен)
A20: 44214 | B20: 15000 | D20: от Ольховского аванс за бабочки и ключи
C21: 480 | D21: электрика в щит ЧПУ
A22: 44215 | B22: 5000 | D22: от кмузова, должен ещё 1500
C23: 4500 | D23: труба на подтумбочники мистер дорс
A24: 44216 | C24: 20500 | D24: Алёне за резку бабочек и ключей для Ользовского
C25: 3600 | D25: Антону за трубу для мистердорс
A26: 44217 | B26: 45000 | D26: Гроссххолод зха сборку щитов
C27: 2700 | D27: налрг за гроссхолод
A28: 44223 | B28: 10000 | D28: от Огнева за кроны
C29: 10000 | D29: лазер на ключи Ольховскому
A30: 44224 | C30: 10000 | D30: Валере за покраску подтумбочников
B31: 2000 | D31: сварка нержавки
A32: 44227 | C32: 4650 | D32: метчики
C33: 5000 | D33: Валере за покраску Огневу кронштейнов
C34: 6300 | D34: Глазкову за резку кронштейнов для огнева
A35: 44228 | B35: 105000 | D35: от Ольховского за Лунтиков и 12 ключей
A36: 44230 | B36: 26000 | D36: от огнева за кроны
A37: 44234 | C37: 2000 | D37: покраска зиговки
C38: 400 | D38: пружины на зиговку
C39: 250 | D39: метизы на зиговку
A40: 44235 | C40: 1000 | D40: Феде за помощь
...

Sheet 20
A1: Дата | B1: Приход | C1: Расход | D1: Комментарий | E1: 365 | F1: Дней с начала года прошло
B2: =SUM(B4:B2131) -> 3509497 | C2: =SUM(C4:C2131) -> 1735936.4 | E2: =B3/E1 -> 4859.0701 | F2: Средний доход за день
A3: остаток | B3: =B2-C2 -> 1773560.6 | E3: =E2/8 -> 607.38377 | F3: =E3*160 -> 97181.403 | G3: Среднее за час\месяц
A4: 43836 | C4: 3900 | D4: алюминий на шкив
C5: 3700 | D5: фанера дэну
A6: 43844 | B6: 35000 | D6: от Ольховского аванс за верстак 50%
B7: 15000 | D7: от Ебобата аванс за стеллаж (из 35)
A8: 43845 | C8: 15000 | D8: Валере аванс за верстак и Ебобата, общ 25+20
A9: 43845 | B9: 7000 | D9: от Михалыча за железяки
C10: 7000 | D10: Ане за железяки
A11: 43483 | B11: 27000 | D11: от Юры за кроны вентиляторов для орехова
C12: 3500 | D12: всякая хрень с Алика
A13: 43850 | B13: 1500 | D13: от дэна за хранение железяк
C14: 4000 | D14: Ане за резку уголков для Ебобата и переделку Зигиных нащельников
A15: 43851 | C15: 3000 | D15: Валере за покраску пёськи и Зигиных нащельников
C16: 8500 | D16: галтовочные тела
C17: 2500 | D17: шлифдиски всякие
A18: 43487 | C18: 10544 | D18: направляйки для ЧПУ
B19: 3000 | D19: от Вовы за покраску пёськи
A20: 43854 | C20: 10000 | D20: Валере остаток за стеллаж Ебобата
A21: 43856 | B21: 20000 | D21: от Ебобата за стеллаж. Расчитался.
C22: 4000 | D22: всякая хрень с Алика
A23: 43857 | B23: 10000 | D23: от Ольховского аванс на болты и гайки из чугуна
C24: 10400 | D24: за чугун для Ольховского
B25: 15000 | D25: от Кирьянова аванс за станок (из 60)
A26: 43861 | C26: 20000 | D26: за лазер на станок Кирьянова и удлинители сварстола
B27: 3000 | D27: от Сорокина за удлинители сварстола
B28: 41000 | D28: за изготовление оснований испытательных для Славы
A29: 43864 | C29: 3084 | D29: ленты для пилы
C30: 850 | D30: всякая мелочёвка для намоточного станка
C31: 20000 | D31: металл за основания стендов для Славы
C32: 500 | D32: разгрузка металла
A33: 43870 | C33: 2500 | D33: Михаоыч
A34: 43871 | B34: 26500 | D34: от Ольховского за болванку из меди и на тиски\гриндер
C35: 16000 | D35: Антону за медь
B36: 1200 | D36: сварка вилки велика
C37: 10450 | D37: тиски и гриндер
A38: 43872 | C38: 20800 | D38: Валере за верстак Ольховского
A39: 43876 | B39: 39900 | D39: От Ольховского остатовк за верстак
B40: 4600 | D40: от Ольховского за электрику
...

Sheet 19
A1: Дата | B1: Приход | C1: Расход | D1: Комментарий | E1: 365 | F1: Дней с начала года прошло
B2: =SUM(B4:B2125) -> 3540824 | C2: =SUM(C4:C2125) -> 1839484 | E2: =B3/E1 -> 4661.2055 | F2: Средний доход за день
A3: остаток | B3: =B2-C2 -> 1701340 | E3: =E2/8 -> 582.65068 | F3: =E3*160 -> 93224.11 | G3: Среднее за час\месяц
A4: 43466 | C4: 12500 | D4: делительная головка
C5: 840 | D5: доставка головки
C6: 4000 | D6: милвоки
B7: 15000 | D7: сварка рамы для Юры
A8: 43477 | C8: 660 | D8: крепмаркет
C9: 2055 | D9: литые кроны
B10: 10000 | D10: аванс за "паровоз"
C11: 6200 | D11: аренда и электричество
C12: 300 | D12: фрезы
C13: 1400 | D13: фрезы
A14: 43480 | C14: 1500 | D14: МКЭШ
C15: 700 | D15: латунные болты
A16: 43482 | B16: 6000 | D16: за рельсодержатель
C17: 632 | D17: чугунина
C18: 883 | D18: опрыскиватель, угольник, маслёнка
C19: 674 | D19: краска для рамочки
A20: 43485 | B20: 5000 | D20: от Павла за парогенератор
C21: 2500 | D21: Юре за парогенер
B22: 10000 | D22: от Юры за сборку Воронежа
B23: 57600 | D23: от Галины за подставки для туббочек
C24: 5200 | D24: металл на подставки
A25: 43127 | C25: 1350 | D25: проволока
A26: 43493 | C26: 6130 | D26: рельсы
A27: 43494 | B27: 2000 | D27: от Кмузова за рельсодержатель
A28: 43495 | C28: 5500 | D28: термосвёрла
A29: 43497 | B29: 10000 | D29: Максим аванс за стол
A30: 43500 | B30: 5000 | D30: от МР за снег
C31: 6000 | D31: Юре за аренду
C32: 7300 | D32: деревяшки для стола
B33: 5000 | D33: Роман аванс за турник
A34: 43502 | B34: 20000 | D34: Евгений за рамку, рассчиталсчя полностью
C35: 5300 | D35: металл для Романа и Максима
C36: 1000 | D36: латунные болты для рамки
A37: 43506 | C37: 900 | D37: абразивные круги
C38: 300 | D38: присадочные прутки
C39: 430 | D39: стремянка от ЗиЛ
A40: 43507 | C40: 2250 | D40: кольцевая фреза и борфреза
...

Sheet 18
A1: Дата | B1: Приход | C1: Расход | D1: Комментарий | F1: б\н Юра
B2: =SUM(B4:B2110) -> 1031550 | C2: =SUM(C4:C2110) -> 535506
A3: остаток | B3: =B2-C2 -> 496044
A4: 43107 | B4: 10000 | D4: предоплата за кабельные стеллажи
A5: 43111 | B5: 1500 | D5: предоплата за 3 волшебные палки
A6: 43114 | B6: 3000 | D6: сварка рамы велосипеда
A7: 43115 | B7: 1500 | D7: ост за 3 палочки
A8: 43115 | B8: 500 | D8: ост. За палочки перед НГ
A9: 43117 | B9: 2000 | D9: предоплата за кашпо
A10: 43121 | B10: 5000 | D10: кронштейны в гараж
A11: 43128 | B11: 5500 | D11: ост за кашпо
A12: 43132 | C12: 3500 | D12: диск по металлу 305
C13: 1360 | D13: фреза Ф8 по алюминию
B14: 4500 | D14: предоплата для сварки швеллера для ванной
C15: 4000 | D15: алюминиевый уголок 80х40х3 для сварки швеллера
A16: 43134 | C16: 6000 | D16: ЛДСП и фурнитура для стеллажей кабельных
B17: 2000 | D17: за фрезеровку крышки от компа
A18: 42772 | B18: 4500 | D18: сварка швеллера алюминиевого.
C19: 3700 | D19: фрезы Олмитул
A20: 42773 | C20: 2100 | D20: фанера на катушки
C21: 1600 | D21: металл Дэнчику на кронштейны
A22: 42774 | C22: 2500 | D22: лаки и краски всякие
C23: 400 | D23: лиственница на птичьи домики
B24: 1500 | D24: аванс на два скворешника
C25: 1900 | D25: фанера на катушки
A26: 43141 | B26: 5000 | D26: кронштейны и длинные хреновины Дэнчику
A27: 43143 | B27: 1500 | D27: оплата за два скворешника
B28: 1000 | D28: аванс за ключи
A29: 43148 | B29: 35000 | D29: оплата за стеллажи кабельные
C30: 250 | D30: железо (пруток и полоса)
A31: 43149 | B31: 4000 | D31: остаток за ключи
A32: 43153 | B32: 11800 | D32: Юра за вентиляторы и сварку каркаса в бронницы
A33: 43156 | C33: 3614 | D33: зенкер, цековка, болтишки
A34: 43157 | C34: 1600 | D34: сверло 5,5, метчики М3 и М4.
B35: 1500 | D35: аванс за кроны для полок
A36: 43158 | C36: 15000 | D36: Милколенточка
A37: 43159 | C37: 3000 | D37: Епсон
A38: 43161 | C38: 1000 | D38: подварка ступицы квадра
A39: 43162 | C39: 312 | D39: металл на кроны для полок
A40: 43163 | B40: 3500 | D40: проточка шаровых
...

Sheet Лист1
A1: год | B1: приход | C1: расход | D1: доход
A2: 2018 | B2: ='18'!B2 -> 1031550 | C2: ='18'!C2 -> 535506 | D2: =B2-C2 -> 496044
A3: 2019 | B3: ='19'!B2 -> 3540824 | C3: ='19'!C2 -> 1839484 | D3: =B3-C3 -> 1701340
A4: 2020 | B4: ='20'!B2 -> 3509497 | C4: ='20'!C2 -> 1735936.4 | D4: =B4-C4 -> 1773560.6
A5: 2021 | B5: ='21'!B2 -> 4818296 | C5: ='21'!C2 -> 2491250.8 | D5: =B5-C5 -> 2327045.2
A6: 2022 | B6: ='22'!B2 -> 10224884 | C6: ='22'!C2 -> 6327440.5 | D6: =B6-C6 -> 3897443.1
